[15/06/2018 15:22] ERROR red <module> 616: Traceback (most recent call last):
  File "lib\discord\http.py", line 258, in static_login
    data = yield from self.request(Route('GET', '/users/@me'))
  File "lib\discord\http.py", line 200, in request
    raise HTTPException(r, data)
discord.errors.HTTPException: UNAUTHORIZED (status code: 401): 401: Unauthorized

The above exception was the direct cause of the following exception:

Traceback (most recent call last):
  File "red.py", line 614, in <module>
    loop.run_until_complete(main(bot))
  File "C:\Users\Cohen Beck\AppData\Local\Programs\Python\Python36-32\lib\asyncio\base_events.py", line 468, in run_until_complete
    return future.result()
  File "red.py", line 599, in main
    bot=not bot.settings.self_bot)
  File "lib\discord\client.py", line 416, in login
    yield from getattr(self, '_login_' + str(n))(*args, **kwargs)
  File "lib\discord\client.py", line 346, in _login_1
    data = yield from self.http.static_login(token, bot=is_bot)
  File "lib\discord\http.py", line 262, in static_login
    raise LoginFailure('Improper token has been passed.') from e
discord.errors.LoginFailure: Improper token has been passed.

